Workbook

Sheet Summary
B2: DarkHorse - Delivery Plan (Azure, Continuum + ChickletFlow integration)
B4: Plan start (Monday, Week 1) | C4: 46321 | D4: Edit this date and every date in the workbook shifts.
B5: Duration | C5: 26 weeks
B6: Baseline | C6: Extension v0.7.38; CPI-6 sprints 1-6 shipped
B7: Architecture | C7: docs/DarkHorse_09_Azure_Deployment.md
B9: Releases
B10: Release | C10: Go-live (Fri) | D10: Scope
B11: R0 | C11: =$C$4+7*(4-1)+4 -> 46346 | D11: R0 - Azure Foundations (dev env live)
B12: MVP | C12: =$C$4+7*(8-1)+4 -> 46374 | D12: MVP - DarkHorse on Azure, Continuum read integration, internal pilot
B13: R2 | C13: =$C$4+7*(14-1)+4 -> 46416 | D13: R2 - Memory, Clean Core loop, full Continuum + ChickletFlow integration
B14: R3 | C14: =$C$4+7*(20-1)+4 -> 46458 | D14: R3 - Marketplace, multi-model, private networking, dashboards
B15: GA | C15: =$C$4+7*(24-1)+4 -> 46486 | D15: GA - Production hardening, client-tenant template, security sign-off
B17: Sheets
B18: Milestones | C18: Key dates and exit criteria
B19: Features | C19: All features, release, status, weeks, effort, dependencies (edit start/end here)
B20: Weekly Timeline | C20: Gantt driven by Features start/end weeks
B21: Release Plan | C21: What goes live in each release and go/no-go
B22: Integration | C22: Changes needed in Continuum, ChickletFlow and DarkHorse
B23: Azure Deployment | C23: Azure rollout phases and environments
B24: Effort by Workstream | C24: Person-weeks per workstream and release
B25: Risks & Questions | C25: Risks and open decisions
B27: Note | C27: Integration changes are based on reading the Continuum (Next.js/Prisma) and ChickletFlow (FastAPI/Alembic) code in C:\99-AI Projects. Effort and week estimates are first-pass and owners are TBD.

Sheet Milestones
A1: # | B1: Milestone | C1: Week | D1: Date (Fri) | E1: Exit criteria
A2: 0 | B2: M0 Kickoff | C2: 1 | D2: =Summary!$C$4+7*(C2-1)+4 -> 46325 | E2: Plan approved, owners assigned, Azure subscription and quota requests opened
A3: 1 | B3: M1 Azure dev live (R0) | C3: 4 | D3: =Summary!$C$4+7*(C3-1)+4 -> 46346 | E3: IaC deployed, containers in ACR, CI/CD green, OpenAI + AI Search provisioned
A4: 2 | B4: M2 Integration contract signed | C4: 4 | D4: =Summary!$C$4+7*(C4-1)+4 -> 46346 | E4: Event/ID contract agreed by DarkHorse, Continuum, ChickletFlow
A5: 3 | B5: M3 MVP feature complete | C5: 7 | D5: =Summary!$C$4+7*(C5-1)+4 -> 46367 | E5: Editor -> APIM -> MCP/LLM proxy -> AI Search working with Entra auth and Continuum read
A6: 4 | B6: M4 MVP go-live on Azure (internal pilot) | C6: 8 | D6: =Summary!$C$4+7*(C6-1)+4 -> 46374 | E6: Prod env up, one real RICEFW end to end, go/no-go passed
A7: 5 | B7: M5 Hypercare exit | C7: 10 | D7: =Summary!$C$4+7*(C7-1)+4 -> 46388 | E7: Stable for 2 weeks, holiday period buffer, defects triaged
A8: 6 | B8: M6 Continuum + ChickletFlow on Azure with SSO | C8: 11 | D8: =Summary!$C$4+7*(C8-1)+4 -> 46395 | E8: Both apps deployed, Entra SSO, auth on ChickletFlow
A9: 7 | B9: M7 R2 release: integrated flow + memory | C9: 14 | D9: =Summary!$C$4+7*(C9-1)+4 -> 46416 | E9: Memory, Clean Core loop, push-back, webhook, StatusReporter live
A10: 8 | B10: M8 R3 release: marketplace + private networking | C10: 20 | D10: =Summary!$C$4+7*(C10-1)+4 -> 46458 | E10: Agent marketplace, multi-model, dashboards, UAT complete
A11: 9 | B11: M9 Security sign-off | C11: 22 | D11: =Summary!$C$4+7*(C11-1)+4 -> 46472 | E11: Pen-test findings closed, DR test passed
A12: 10 | B12: M10 GA | C12: 24 | D12: =Summary!$C$4+7*(C12-1)+4 -> 46486 | E12: Production release, client-tenant template, support model live

Sheet Features
A1: ID | B1: Workstream | C1: Feature | D1: Description | E1: Release | F1: Release week | G1: Priority | H1: Status | I1: Start wk | J1: End wk | K1: Start date | L1: End date | M1: Person-weeks | N1: Depends on | O1: Owner | P1: MVP?
A2: A1 | B2: Azure Platform | C2: Azure landing zone + IaC | D2: Bicep/Terraform: resource groups (dev/prod), Key Vault, ACR, Log Analytics, tagging, RBAC | E2: R0 | F2: =IFERROR(VLOOKUP(E2,'Release Plan'!$A$5:$C$9,3,FALSE),"") -> 4 | G2: High | H2: Planned | I2: 1 | J2: 3 | K2: =Summary!$C$4+7*(I2-1) -> 46321 | L2: =Summary!$C$4+7*(J2-1)+4 -> 46339 | M2: 3 | O2: TBD | P2: Yes
A3: A2 | B3: Azure Platform | C3: Azure OpenAI / Foundry deployments | D3: Chat model + text-embedding-3 deployments; quota request; region and data-residency decision | E3: R0 | F3: =IFERROR(VLOOKUP(E3,'Release Plan'!$A$5:$C$9,3,FALSE),"") -> 4 | G3: High | H3: Planned | I3: 1 | J3: 3 | K3: =Summary!$C$4+7*(I3-1) -> 46321 | L3: =Summary!$C$4+7*(J3-1)+4 -> 46339 | M3: 1 | O3: TBD | P3: Yes
A4: A3 | B4: Azure Platform | C4: Azure AI Search + index schema v2 | D4: Standard S1, semantic ranker, hybrid index with metadata fields (object type, C1 status, S/4 version, source) | E4: R0 | F4: =IFERROR(VLOOKUP(E4,'Release Plan'!$A$5:$C$9,3,FALSE),"") -> 4 | G4: High | H4: Planned | I4: 2 | J4: 4 | K4: =Summary!$C$4+7*(I4-1) -> 46328 | L4: =Summary!$C$4+7*(J4-1)+4 -> 46346 | M4: 2 | N4: A1 | O4: TBD | P4: Yes
A5: A4 | B5: Azure Platform | C5: Containerize services | D5: Dockerfiles for darkhorse-mcp, llm-proxy, ingest job (with headless Chromium), agent service; push to ACR | E5: R0 | F5: =IFERROR(VLOOKUP(E5,'Release Plan'!$A$5:$C$9,3,FALSE),"") -> 4 | G5: High | H5: Planned | I5: 3 | J5: 4 | K5: =Summary!$C$4+7*(I5-1) -> 46335 | L5: =Summary!$C$4+7*(J5-1)+4 -> 46346 | M5: 2 | N5: A1 | O5: TBD | P5: Yes
A6: A5 | B6: Azure Platform | C6: Container Apps env + APIM + Front Door | D6: Internal ingress behind APIM, custom domain, rate limits, audit logging | E6: MVP | F6: =IFERROR(VLOOKUP(E6,'Release Plan'!$A$5:$C$9,3,FALSE),"") -> 8 | G6: High | H6: Planned | I6: 4 | J6: 6 | K6: =Summary!$C$4+7*(I6-1) -> 46342 | L6: =Summary!$C$4+7*(J6-1)+4 -> 46360 | M6: 3 | N6: A4 | O6: TBD | P6: Yes
A7: A6 | B7: Azure Platform | C7: Entra ID auth + managed identity | D7: App registration, JWT validation in APIM, replace API keys (Search, OpenAI, Cosmos) with managed identity | E7: MVP | F7: =IFERROR(VLOOKUP(E7,'Release Plan'!$A$5:$C$9,3,FALSE),"") -> 8 | G7: High | H7: Planned | I7: 4 | J7: 7 | K7: =Summary!$C$4+7*(I7-1) -> 46342 | L7: =Summary!$C$4+7*(J7-1)+4 -> 46367 | M7: 3 | N7: A5 | O7: TBD | P7: Yes
A8: A7 | B8: Azure Platform | C8: CI/CD pipelines | D8: GitHub Actions: build, test, image scan, deploy dev/prod, scheduled ingest | E8: R0 | F8: =IFERROR(VLOOKUP(E8,'Release Plan'!$A$5:$C$9,3,FALSE),"") -> 4 | G8: High | H8: Planned | I8: 3 | J8: 4 | K8: =Summary!$C$4+7*(I8-1) -> 46335 | L8: =Summary!$C$4+7*(J8-1)+4 -> 46346 | M8: 2 | N8: A1 | O8: TBD | P8: Yes
A9: A8 | B9: Azure Platform | C9: Observability + cost controls | D9: App Insights, dashboards, alerts, budgets, token usage metering | E9: MVP | F9: =IFERROR(VLOOKUP(E9,'Release Plan'!$A$5:$C$9,3,FALSE),"") -> 8 | G9: Med | H9: Planned | I9: 6 | J9: 8 | K9: =Summary!$C$4+7*(I9-1) -> 46356 | L9: =Summary!$C$4+7*(J9-1)+4 -> 46374 | M9: 2 | N9: A5 | O9: TBD | P9: Yes
A10: A9 | B10: Azure Platform | C10: Prod environment + go-live runbook | D10: Prod resources, smoke tests, rollback plan, on-call, MVP cutover | E10: MVP | F10: =IFERROR(VLOOKUP(E10,'Release Plan'!$A$5:$C$9,3,FALSE),"") -> 8 | G10: High | H10: Planned | I10: 7 | J10: 8 | K10: =Summary!$C$4+7*(I10-1) -> 46363 | L10: =Summary!$C$4+7*(J10-1)+4 -> 46374 | M10: 2 | N10: A6,A8 | O10: TBD | P10: Yes
A11: A10 | B11: Azure Platform | C11: Private networking | D11: VNet integration, Private Endpoints for OpenAI/Search/Cosmos, no public access option | E11: R3 | F11: =IFERROR(VLOOKUP(E11,'Release Plan'!$A$5:$C$9,3,FALSE),"") -> 20 | G11: Med | H11: Planned | I11: 16 | J11: 20 | K11: =Summary!$C$4+7*(I11-1) -> 46426 | L11: =Summary!$C$4+7*(J11-1)+4 -> 46458 | M11: 4 | N11: A9 | O11: TBD
A12: A11 | B12: Azure Platform | C12: Per-client deployment template | D12: Parameterized IaC for deployment into a client subscription/tenant + onboarding guide | E12: GA | F12: =IFERROR(VLOOKUP(E12,'Release Plan'!$A$5:$C$9,3,FALSE),"") -> 24 | G12: High | H12: Planned | I12: 20 | J12: 23 | K12: =Summary!$C$4+7*(I12-1) -> 46454 | L12: =Summary!$C$4+7*(J12-1)+4 -> 46479 | M12: 4 | N12: A10 | O12: TBD
A13: A12 | B13: Azure Platform | C13: DR, backup, load and pen-test remediation | D13: Backups, RPO/RTO test, load test, fix security findings | E13: GA | F13: =IFERROR(VLOOKUP(E13,'Release Plan'!$A$5:$C$9,3,FALSE),"") -> 24 | G13: High | H13: Planned | I13: 21 | J13: 24 | K13: =Summary!$C$4+7*(I13-1) -> 46461 | L13: =Summary!$C$4+7*(J13-1)+4 -> 46486 | M13: 3 | N13: A9 | O13: TBD
A14: B0 | B14: RAG & Knowledge | C14: Ingest framework + 8 fetchers + Azure embedder/index | D14: IFetcher/IChunker/IEmbedder/IVectorIndex; API Hub, Clean Core Guide, Arch Center, Help Portal | E14: Shipped | G14: High | H14: Done | M14: 0 | O14: TBD
A15: B1 | B15: RAG & Knowledge | C15: Scheduled ingest job on Azure | D15: Container Apps Job (nightly/weekly), run history, failure alerts | E15: MVP | F15: =IFERROR(VLOOKUP(E15,'Release Plan'!$A$5:$C$9,3,FALSE),"") -> 8 | G15: High | H15: Planned | I15: 5 | J15: 7 | K15: =Summary!$C$4+7*(I15-1) -> 46349 | L15: =Summary!$C$4+7*(J15-1)+4 -> 46367 | M15: 2 | N15: A4,A3 | O15: TBD | P15: Yes
A16: B2 | B16: RAG & Knowledge | C16: Re-ingest KB with hybrid + metadata filters | D16: Re-embed existing sources into index v2; released-API / S/4 version / object type filters | E16: MVP | F16: =IFERROR(VLOOKUP(E16,'Release Plan'!$A$5:$C$9,3,FALSE),"") -> 8 | G16: High | H16: Planned | I16: 5 | J16: 8 | K16: =Summary!$C$4+7*(I16-1) -> 46349 | L16: =Summary!$C$4+7*(J16-1)+4 -> 46374 | M16: 3 | N16: A3,A2 | O16: TBD | P16: Yes
A17: B3 | B17: RAG & Knowledge | C17: EDMX live run (XSUAA auth) | D17: BTP trial / bearer token path to download EDMX from API Hub | E17: R2 | F17: =IFERROR(VLOOKUP(E17,'Release Plan'!$A$5:$C$9,3,FALSE),"") -> 14 | G17: High | H17: Planned | I17: 9 | J17: 12 | K17: =Summary!$C$4+7*(I17-1) -> 46377 | L17: =Summary!$C$4+7*(J17-1)+4 -> 46402 | M17: 2 | N17: B1 | O17: TBD
A18: B4 | B18: RAG & Knowledge | C18: help-portal-cds re-crawl | D18: Re-crawl per-view detail pages to capture ABAP technical names | E18: R2 | F18: =IFERROR(VLOOKUP(E18,'Release Plan'!$A$5:$C$9,3,FALSE),"") -> 14 | G18: Med | H18: Planned | I18: 10 | J18: 13 | K18: =Summary!$C$4+7*(I18-1) -> 46384 | L18: =Summary!$C$4+7*(J18-1)+4 -> 46409 | M18: 2 | N18: B1 | O18: TBD
A19: B5 | B19: RAG & Knowledge | C19: KB coverage gap closure | D19: Close gaps from DarkHorse_08_KB_Assessment.md (BAdIs, RAP, CBO patterns, released API lists) | E19: R2 | F19: =IFERROR(VLOOKUP(E19,'Release Plan'!$A$5:$C$9,3,FALSE),"") -> 14 | G19: High | H19: Planned | I19: 11 | J19: 14 | K19: =Summary!$C$4+7*(I19-1) -> 46391 | L19: =Summary!$C$4+7*(J19-1)+4 -> 46416 | M19: 4 | N19: B8 | O19: TBD
A20: B6 | B20: RAG & Knowledge | C20: LearningPortalFetcher | D20: Lowest-priority additional source | E20: R3 | F20: =IFERROR(VLOOKUP(E20,'Release Plan'!$A$5:$C$9,3,FALSE),"") -> 20 | G20: Low | H20: Planned | I20: 17 | J20: 19 | K20: =Summary!$C$4+7*(I20-1) -> 46433 | L20: =Summary!$C$4+7*(J20-1)+4 -> 46451 | M20: 1 | N20: B1 | O20: TBD
A21: B7 | B21: RAG & Knowledge | C21: Blob raw cache + ingest versioning | D21: Store raw fetched docs in Blob, version index builds, rollback to previous index | E21: R2 | F21: =IFERROR(VLOOKUP(E21,'Release Plan'!$A$5:$C$9,3,FALSE),"") -> 14 | G21: Med | H21: Planned | I21: 9 | J21: 11 | K21: =Summary!$C$4+7*(I21-1) -> 46377 | L21: =Summary!$C$4+7*(J21-1)+4 -> 46395 | M21: 2 | N21: B1 | O21: TBD
A22: B8 | B22: RAG & Knowledge | C22: Retrieval quality eval harness | D22: Golden set of Clean Core questions; precision/recall, groundedness checks; run on every KB change | E22: MVP | F22: =IFERROR(VLOOKUP(E22,'Release Plan'!$A$5:$C$9,3,FALSE),"") -> 8 | G22: High | H22: Planned | I22: 6 | J22: 8 | K22: =Summary!$C$4+7*(I22-1) -> 46356 | L22: =Summary!$C$4+7*(J22-1)+4 -> 46374 | M22: 2 | N22: B2 | O22: TBD | P22: Yes
A23: C1 | B23: MCP Server | C23: MCP tools (verify_badi/exit, clean core level, CDS, EML, RAP, CBO) | D23: Local MCP server with 9+ tools and static + Azure KnowledgeProvider | E23: Shipped | G23: High | H23: Done | M23: 0 | O23: TBD
A24: C2 | B24: MCP Server | C24: MCP HTTP/SSE transport + auth middleware | D24: Confirm/enable network transport; validate Entra token; per-request tenant context | E24: MVP | F24: =IFERROR(VLOOKUP(E24,'Release Plan'!$A$5:$C$9,3,FALSE),"") -> 8 | G24: High | H24: Planned | I24: 3 | J24: 5 | K24: =Summary!$C$4+7*(I24-1) -> 46335 | L24: =Summary!$C$4+7*(J24-1)+4 -> 46353 | M24: 2 | O24: TBD | P24: Yes
A25: C3 | B25: MCP Server | C25: MCP uses managed identity for Search | D25: Remove AZURE_SEARCH_KEY; Search Index Data Reader role | E25: MVP | F25: =IFERROR(VLOOKUP(E25,'Release Plan'!$A$5:$C$9,3,FALSE),"") -> 8 | G25: High | H25: Planned | I25: 5 | J25: 6 | K25: =Summary!$C$4+7*(I25-1) -> 46349 | L25: =Summary!$C$4+7*(J25-1)+4 -> 46360 | M25: 1 | N25: C2,A6 | O25: TBD | P25: Yes
A26: C4 | B26: MCP Server | C26: New MCP tools | D26: get_released_api, check_atc_cleancore, search_memory, save_memory | E26: R2 | F26: =IFERROR(VLOOKUP(E26,'Release Plan'!$A$5:$C$9,3,FALSE),"") -> 14 | G26: High | H26: Planned | I26: 12 | J26: 14 | K26: =Summary!$C$4+7*(I26-1) -> 46398 | L26: =Summary!$C$4+7*(J26-1)+4 -> 46416 | M26: 3 | N26: E2 | O26: TBD
A27: C5 | B27: MCP Server | C27: MCP rate limits, audit logs, tenant filters | D27: Usage audit and per-client index filtering | E27: R2 | F27: =IFERROR(VLOOKUP(E27,'Release Plan'!$A$5:$C$9,3,FALSE),"") -> 14 | G27: Med | H27: Planned | I27: 13 | J27: 14 | K27: =Summary!$C$4+7*(I27-1) -> 46405 | L27: =Summary!$C$4+7*(J27-1)+4 -> 46416 | M27: 2 | N27: C2 | O27: TBD
A28: D1 | B28: Agents & Pipeline | C28: Grounded Code/TDS/SO/FDS agents | D28: Agents call MCP for grounding before generation (CPI-6 sprints 3-5) | E28: Shipped | G28: High | H28: Done | M28: 0 | O28: TBD
A29: D2 | B29: Agents & Pipeline | C29: ReviewAgent + auto-rewrite + ZI_ wrappers | D29: Independent LLM critic, direct-table SELECT rewrite, auto CDS wrappers (sprint 6) | E29: Shipped | G29: High | H29: Done | M29: 0 | O29: TBD
A30: D3 | B30: Agents & Pipeline | C30: TdsPostCodeAgent | D30: Fills TDS program logic, CDS defs, test cases after code gen | E30: Shipped | G30: Med | H30: Done | M30: 0 | O30: TBD
A31: D4 | B31: Agents & Pipeline | C31: Solution architecture diagram | D31: Mermaid call/dependency graph after code generation | E31: Shipped | G31: Med | H31: Done | M31: 0 | O31: TBD
A32: D5 | B32: Agents & Pipeline | C32: Headless agent service on Azure | D32: Extract pipeline orchestration from the extension into a service API so Continuum/ChickletFlow can trigger runs | E32: R2 | F32: =IFERROR(VLOOKUP(E32,'Release Plan'!$A$5:$C$9,3,FALSE),"") -> 14 | G32: High | H32: Planned | I32: 9 | J32: 14 | K32: =Summary!$C$4+7*(I32-1) -> 46377 | L32: =Summary!$C$4+7*(J32-1)+4 -> 46416 | M32: 6 | N32: D6,C2 | O32: TBD
A33: D6 | B33: Agents & Pipeline | C33: LLM proxy on Azure | D33: Azure OpenAI backend via adapter, PII/secret scrubbing, token metering, retries | E33: MVP | F33: =IFERROR(VLOOKUP(E33,'Release Plan'!$A$5:$C$9,3,FALSE),"") -> 8 | G33: High | H33: Planned | I33: 4 | J33: 7 | K33: =Summary!$C$4+7*(I33-1) -> 46342 | L33: =Summary!$C$4+7*(J33-1)+4 -> 46367 | M33: 3 | N33: A2,A5 | O33: TBD | P33: Yes
A34: D7 | B34: Agents & Pipeline | C34: Clean Core validation loop | D34: Generate, validate vs released APIs / ATC Clean Core, auto-retry, log violations for KB gaps | E34: R2 | F34: =IFERROR(VLOOKUP(E34,'Release Plan'!$A$5:$C$9,3,FALSE),"") -> 14 | G34: High | H34: Planned | I34: 9 | J34: 13 | K34: =Summary!$C$4+7*(I34-1) -> 46377 | L34: =Summary!$C$4+7*(J34-1)+4 -> 46409 | M34: 4 | N34: B2,C2 | O34: TBD
A35: D8 | B35: Agents & Pipeline | C35: Source citations in generated output | D35: Attach retrieved chunk references to generated TDS/code | E35: R2 | F35: =IFERROR(VLOOKUP(E35,'Release Plan'!$A$5:$C$9,3,FALSE),"") -> 14 | G35: Med | H35: Planned | I35: 12 | J35: 14 | K35: =Summary!$C$4+7*(I35-1) -> 46398 | L35: =Summary!$C$4+7*(J35-1)+4 -> 46416 | M35: 2 | N35: D7 | O35: TBD
A36: D9 | B36: Agents & Pipeline | C36: Agent marketplace (Sprint 7) | D36: Catalog, install and versioning of agents per docs/DarkHorse_06 Sprint 7 | E36: R3 | F36: =IFERROR(VLOOKUP(E36,'Release Plan'!$A$5:$C$9,3,FALSE),"") -> 20 | G36: Med | H36: Planned | I36: 15 | J36: 20 | K36: =Summary!$C$4+7*(I36-1) -> 46419 | L36: =Summary!$C$4+7*(J36-1)+4 -> 46458 | M36: 6 | N36: D5 | O36: TBD
A37: D10 | B37: Agents & Pipeline | C37: Multi-model routing | D37: Azure OpenAI / Claude on Foundry / Ollama via adapter; per-agent model choice | E37: R3 | F37: =IFERROR(VLOOKUP(E37,'Release Plan'!$A$5:$C$9,3,FALSE),"") -> 20 | G37: Med | H37: Planned | I37: 14 | J37: 17 | K37: =Summary!$C$4+7*(I37-1) -> 46412 | L37: =Summary!$C$4+7*(J37-1)+4 -> 46437 | M37: 3 | N37: D6 | O37: TBD
A38: D11 | B38: Agents & Pipeline | C38: Prompt registry + eval regression suite | D38: Versioned prompts, automated regression on golden FDS/TDS set | E38: R3 | F38: =IFERROR(VLOOKUP(E38,'Release Plan'!$A$5:$C$9,3,FALSE),"") -> 20 | G38: Med | H38: Planned | I38: 16 | J38: 19 | K38: =Summary!$C$4+7*(I38-1) -> 46426 | L38: =Summary!$C$4+7*(J38-1)+4 -> 46451 | M38: 3 | N38: B8 | O38: TBD
A39: E1 | B39: Memory | C39: Cosmos DB + memory schema | D39: Provision Cosmos; session/project/user memory containers; partition by client/project | E39: R2 | F39: =IFERROR(VLOOKUP(E39,'Release Plan'!$A$5:$C$9,3,FALSE),"") -> 14 | G39: High | H39: Planned | I39: 8 | J39: 10 | K39: =Summary!$C$4+7*(I39-1) -> 46370 | L39: =Summary!$C$4+7*(J39-1)+4 -> 46388 | M39: 2 | N39: A6 | O39: TBD
A40: E2 | B40: Memory | C40: Session & project memory API | D40: Memory read/write service + MCP tools; agents recall prior decisions | E40: R2 | F40: =IFERROR(VLOOKUP(E40,'Release Plan'!$A$5:$C$9,3,FALSE),"") -> 14 | G40: High | H40: Planned | I40: 10 | J40: 13 | K40: =Summary!$C$4+7*(I40-1) -> 46384 | L40: =Summary!$C$4+7*(J40-1)+4 -> 46409 | M40: 3 | N40: E1 | O40: TBD
...

Sheet Weekly Timeline
A1: Weekly timeline (driven by Features start/end week; change them in Features)
B3: Week starting (Mon) | F3: =Summary!$C$4+7*(F4-1) -> 46321 | G3: =Summary!$C$4+7*(G4-1) -> 46328 | H3: =Summary!$C$4+7*(H4-1) -> 46335 | I3: =Summary!$C$4+7*(I4-1) -> 46342 | J3: =Summary!$C$4+7*(J4-1) -> 46349 | K3: =Summary!$C$4+7*(K4-1) -> 46356 | L3: =Summary!$C$4+7*(L4-1) -> 46363 | M3: =Summary!$C$4+7*(M4-1) -> 46370 | ... AE3: =Summary!$C$4+7*(AE4-1) -> 46496
A4: ID | B4: Feature | C4: Release | D4: Start | E4: End | F4: 1 | G4: 2 | H4: 3 | I4: 4 | J4: 5 | K4: 6 | L4: 7 | M4: 8 | N4: 9 | O4: 10 | P4: 11 | Q4: 12 | R4: 13 | S4: 14 | T4: 15 | U4: 16 | V4: 17 | W4: 18 | X4: 19 | Y4: 20 | Z4: 21 | AA4: 22 | AB4: 23 | AC4: 24 | AD4: 25 | AE4: 26
B5: Milestones (diamond) | F5: =IF(COUNTIF(Milestones!$C$2:$C$12,F$4)>0,"◆","") -> ◆ | G5: =IF(COUNTIF(Milestones!$C$2:$C$12,G$4)>0,"◆","") | H5: =IF(COUNTIF(Milestones!$C$2:$C$12,H$4)>0,"◆","") | I5: =IF(COUNTIF(Milestones!$C$2:$C$12,I$4)>0,"◆","") -> ◆ | J5: =IF(COUNTIF(Milestones!$C$2:$C$12,J$4)>0,"◆","") | K5: =IF(COUNTIF(Milestones!$C$2:$C$12,K$4)>0,"◆","") | L5: =IF(COUNTIF(Milestones!$C$2:$C$12,L$4)>0,"◆","") -> ◆ | M5: =IF(COUNTIF(Milestones!$C$2:$C$12,M$4)>0,"◆","") -> ◆ | ... AE5: =IF(COUNTIF(Milestones!$C$2:$C$12,AE$4)>0,"◆","")
B6: Releases (R0/MVP/R2/R3/GA) | F6: =IFERROR(INDEX('Release Plan'!$A$5:$A$9,MATCH(F$4,'Release Plan'!$C$5:$C$9,0)),"") | G6: =IFERROR(INDEX('Release Plan'!$A$5:$A$9,MATCH(G$4,'Release Plan'!$C$5:$C$9,0)),"") | H6: =IFERROR(INDEX('Release Plan'!$A$5:$A$9,MATCH(H$4,'Release Plan'!$C$5:$C$9,0)),"") | I6: =IFERROR(INDEX('Release Plan'!$A$5:$A$9,MATCH(I$4,'Release Plan'!$C$5:$C$9,0)),"") -> R0 | J6: =IFERROR(INDEX('Release Plan'!$A$5:$A$9,MATCH(J$4,'Release Plan'!$C$5:$C$9,0)),"") | K6: =IFERROR(INDEX('Release Plan'!$A$5:$A$9,MATCH(K$4,'Release Plan'!$C$5:$C$9,0)),"") | L6: =IFERROR(INDEX('Release Plan'!$A$5:$A$9,MATCH(L$4,'Release Plan'!$C$5:$C$9,0)),"") | M6: =IFERROR(INDEX('Release Plan'!$A$5:$A$9,MATCH(M$4,'Release Plan'!$C$5:$C$9,0)),"") -> MVP | ... AE6: =IFERROR(INDEX('Release Plan'!$A$5:$A$9,MATCH(AE$4,'Release Plan'!$C$5:$C$9,0)),"")
A7: Azure Platform
A8: =Features!A2 -> A1 | B8: =Features!C2 -> Azure landing zone + IaC | C8: =Features!E2 -> R0 | D8: =Features!I2 -> 1 | E8: =Features!J2 -> 3 | F8: =IF(AND(F$4>=$D8,F$4<=$E8),1,"") -> 1 | G8: =IF(AND(G$4>=$D8,G$4<=$E8),1,"") -> 1 | H8: =IF(AND(H$4>=$D8,H$4<=$E8),1,"") -> 1 | I8: =IF(AND(I$4>=$D8,I$4<=$E8),1,"") | J8: =IF(AND(J$4>=$D8,J$4<=$E8),1,"") | K8: =IF(AND(K$4>=$D8,K$4<=$E8),1,"") | L8: =IF(AND(L$4>=$D8,L$4<=$E8),1,"") | M8: =IF(AND(M$4>=$D8,M$4<=$E8),1,"") | ... AE8: =IF(AND(AE$4>=$D8,AE$4<=$E8),1,"")
A9: =Features!A3 -> A2 | B9: =Features!C3 -> Azure OpenAI / Foundry deployments | C9: =Features!E3 -> R0 | D9: =Features!I3 -> 1 | E9: =Features!J3 -> 3 | F9: =IF(AND(F$4>=$D9,F$4<=$E9),1,"") -> 1 | G9: =IF(AND(G$4>=$D9,G$4<=$E9),1,"") -> 1 | H9: =IF(AND(H$4>=$D9,H$4<=$E9),1,"") -> 1 | I9: =IF(AND(I$4>=$D9,I$4<=$E9),1,"") | J9: =IF(AND(J$4>=$D9,J$4<=$E9),1,"") | K9: =IF(AND(K$4>=$D9,K$4<=$E9),1,"") | L9: =IF(AND(L$4>=$D9,L$4<=$E9),1,"") | M9: =IF(AND(M$4>=$D9,M$4<=$E9),1,"") | ... AE9: =IF(AND(AE$4>=$D9,AE$4<=$E9),1,"")
A10: =Features!A4 -> A3 | B10: =Features!C4 -> Azure AI Search + index schema v2 | C10: =Features!E4 -> R0 | D10: =Features!I4 -> 2 | E10: =Features!J4 -> 4 | F10: =IF(AND(F$4>=$D10,F$4<=$E10),1,"") | G10: =IF(AND(G$4>=$D10,G$4<=$E10),1,"") -> 1 | H10: =IF(AND(H$4>=$D10,H$4<=$E10),1,"") -> 1 | I10: =IF(AND(I$4>=$D10,I$4<=$E10),1,"") -> 1 | J10: =IF(AND(J$4>=$D10,J$4<=$E10),1,"") | K10: =IF(AND(K$4>=$D10,K$4<=$E10),1,"") | L10: =IF(AND(L$4>=$D10,L$4<=$E10),1,"") | M10: =IF(AND(M$4>=$D10,M$4<=$E10),1,"") | ... AE10: =IF(AND(AE$4>=$D10,AE$4<=$E10),1,"")
A11: =Features!A5 -> A4 | B11: =Features!C5 -> Containerize services | C11: =Features!E5 -> R0 | D11: =Features!I5 -> 3 | E11: =Features!J5 -> 4 | F11: =IF(AND(F$4>=$D11,F$4<=$E11),1,"") | G11: =IF(AND(G$4>=$D11,G$4<=$E11),1,"") | H11: =IF(AND(H$4>=$D11,H$4<=$E11),1,"") -> 1 | I11: =IF(AND(I$4>=$D11,I$4<=$E11),1,"") -> 1 | J11: =IF(AND(J$4>=$D11,J$4<=$E11),1,"") | K11: =IF(AND(K$4>=$D11,K$4<=$E11),1,"") | L11: =IF(AND(L$4>=$D11,L$4<=$E11),1,"") | M11: =IF(AND(M$4>=$D11,M$4<=$E11),1,"") | ... AE11: =IF(AND(AE$4>=$D11,AE$4<=$E11),1,"")
A12: =Features!A6 -> A5 | B12: =Features!C6 -> Container Apps env + APIM + Front Door | C12: =Features!E6 -> MVP | D12: =Features!I6 -> 4 | E12: =Features!J6 -> 6 | F12: =IF(AND(F$4>=$D12,F$4<=$E12),1,"") | G12: =IF(AND(G$4>=$D12,G$4<=$E12),1,"") | H12: =IF(AND(H$4>=$D12,H$4<=$E12),1,"") | I12: =IF(AND(I$4>=$D12,I$4<=$E12),1,"") -> 1 | J12: =IF(AND(J$4>=$D12,J$4<=$E12),1,"") -> 1 | K12: =IF(AND(K$4>=$D12,K$4<=$E12),1,"") -> 1 | L12: =IF(AND(L$4>=$D12,L$4<=$E12),1,"") | M12: =IF(AND(M$4>=$D12,M$4<=$E12),1,"") | ... AE12: =IF(AND(AE$4>=$D12,AE$4<=$E12),1,"")
A13: =Features!A7 -> A6 | B13: =Features!C7 -> Entra ID auth + managed identity | C13: =Features!E7 -> MVP | D13: =Features!I7 -> 4 | E13: =Features!J7 -> 7 | F13: =IF(AND(F$4>=$D13,F$4<=$E13),1,"") | G13: =IF(AND(G$4>=$D13,G$4<=$E13),1,"") | H13: =IF(AND(H$4>=$D13,H$4<=$E13),1,"") | I13: =IF(AND(I$4>=$D13,I$4<=$E13),1,"") -> 1 | J13: =IF(AND(J$4>=$D13,J$4<=$E13),1,"") -> 1 | K13: =IF(AND(K$4>=$D13,K$4<=$E13),1,"") -> 1 | L13: =IF(AND(L$4>=$D13,L$4<=$E13),1,"") -> 1 | M13: =IF(AND(M$4>=$D13,M$4<=$E13),1,"") | ... AE13: =IF(AND(AE$4>=$D13,AE$4<=$E13),1,"")
A14: =Features!A8 -> A7 | B14: =Features!C8 -> CI/CD pipelines | C14: =Features!E8 -> R0 | D14: =Features!I8 -> 3 | E14: =Features!J8 -> 4 | F14: =IF(AND(F$4>=$D14,F$4<=$E14),1,"") | G14: =IF(AND(G$4>=$D14,G$4<=$E14),1,"") | H14: =IF(AND(H$4>=$D14,H$4<=$E14),1,"") -> 1 | I14: =IF(AND(I$4>=$D14,I$4<=$E14),1,"") -> 1 | J14: =IF(AND(J$4>=$D14,J$4<=$E14),1,"") | K14: =IF(AND(K$4>=$D14,K$4<=$E14),1,"") | L14: =IF(AND(L$4>=$D14,L$4<=$E14),1,"") | M14: =IF(AND(M$4>=$D14,M$4<=$E14),1,"") | ... AE14: =IF(AND(AE$4>=$D14,AE$4<=$E14),1,"")
A15: =Features!A9 -> A8 | B15: =Features!C9 -> Observability + cost controls | C15: =Features!E9 -> MVP | D15: =Features!I9 -> 6 | E15: =Features!J9 -> 8 | F15: =IF(AND(F$4>=$D15,F$4<=$E15),1,"") | G15: =IF(AND(G$4>=$D15,G$4<=$E15),1,"") | H15: =IF(AND(H$4>=$D15,H$4<=$E15),1,"") | I15: =IF(AND(I$4>=$D15,I$4<=$E15),1,"") | J15: =IF(AND(J$4>=$D15,J$4<=$E15),1,"") | K15: =IF(AND(K$4>=$D15,K$4<=$E15),1,"") -> 1 | L15: =IF(AND(L$4>=$D15,L$4<=$E15),1,"") -> 1 | M15: =IF(AND(M$4>=$D15,M$4<=$E15),1,"") -> 1 | ... AE15: =IF(AND(AE$4>=$D15,AE$4<=$E15),1,"")
A16: =Features!A10 -> A9 | B16: =Features!C10 -> Prod environment + go-live runbook | C16: =Features!E10 -> MVP | D16: =Features!I10 -> 7 | E16: =Features!J10 -> 8 | F16: =IF(AND(F$4>=$D16,F$4<=$E16),1,"") | G16: =IF(AND(G$4>=$D16,G$4<=$E16),1,"") | H16: =IF(AND(H$4>=$D16,H$4<=$E16),1,"") | I16: =IF(AND(I$4>=$D16,I$4<=$E16),1,"") | J16: =IF(AND(J$4>=$D16,J$4<=$E16),1,"") | K16: =IF(AND(K$4>=$D16,K$4<=$E16),1,"") | L16: =IF(AND(L$4>=$D16,L$4<=$E16),1,"") -> 1 | M16: =IF(AND(M$4>=$D16,M$4<=$E16),1,"") -> 1 | ... AE16: =IF(AND(AE$4>=$D16,AE$4<=$E16),1,"")
A17: =Features!A11 -> A10 | B17: =Features!C11 -> Private networking | C17: =Features!E11 -> R3 | D17: =Features!I11 -> 16 | E17: =Features!J11 -> 20 | F17: =IF(AND(F$4>=$D17,F$4<=$E17),1,"") | G17: =IF(AND(G$4>=$D17,G$4<=$E17),1,"") | H17: =IF(AND(H$4>=$D17,H$4<=$E17),1,"") | I17: =IF(AND(I$4>=$D17,I$4<=$E17),1,"") | J17: =IF(AND(J$4>=$D17,J$4<=$E17),1,"") | K17: =IF(AND(K$4>=$D17,K$4<=$E17),1,"") | L17: =IF(AND(L$4>=$D17,L$4<=$E17),1,"") | M17: =IF(AND(M$4>=$D17,M$4<=$E17),1,"") | ... AE17: =IF(AND(AE$4>=$D17,AE$4<=$E17),1,"")
A18: =Features!A12 -> A11 | B18: =Features!C12 -> Per-client deployment template | C18: =Features!E12 -> GA | D18: =Features!I12 -> 20 | E18: =Features!J12 -> 23 | F18: =IF(AND(F$4>=$D18,F$4<=$E18),1,"") | G18: =IF(AND(G$4>=$D18,G$4<=$E18),1,"") | H18: =IF(AND(H$4>=$D18,H$4<=$E18),1,"") | I18: =IF(AND(I$4>=$D18,I$4<=$E18),1,"") | J18: =IF(AND(J$4>=$D18,J$4<=$E18),1,"") | K18: =IF(AND(K$4>=$D18,K$4<=$E18),1,"") | L18: =IF(AND(L$4>=$D18,L$4<=$E18),1,"") | M18: =IF(AND(M$4>=$D18,M$4<=$E18),1,"") | ... AE18: =IF(AND(AE$4>=$D18,AE$4<=$E18),1,"")
A19: =Features!A13 -> A12 | B19: =Features!C13 -> DR, backup, load and pen-test remediation | C19: =Features!E13 -> GA | D19: =Features!I13 -> 21 | E19: =Features!J13 -> 24 | F19: =IF(AND(F$4>=$D19,F$4<=$E19),1,"") | G19: =IF(AND(G$4>=$D19,G$4<=$E19),1,"") | H19: =IF(AND(H$4>=$D19,H$4<=$E19),1,"") | I19: =IF(AND(I$4>=$D19,I$4<=$E19),1,"") | J19: =IF(AND(J$4>=$D19,J$4<=$E19),1,"") | K19: =IF(AND(K$4>=$D19,K$4<=$E19),1,"") | L19: =IF(AND(L$4>=$D19,L$4<=$E19),1,"") | M19: =IF(AND(M$4>=$D19,M$4<=$E19),1,"") | ... AE19: =IF(AND(AE$4>=$D19,AE$4<=$E19),1,"")
A20: RAG & Knowledge
A21: =Features!A15 -> B1 | B21: =Features!C15 -> Scheduled ingest job on Azure | C21: =Features!E15 -> MVP | D21: =Features!I15 -> 5 | E21: =Features!J15 -> 7 | F21: =IF(AND(F$4>=$D21,F$4<=$E21),1,"") | G21: =IF(AND(G$4>=$D21,G$4<=$E21),1,"") | H21: =IF(AND(H$4>=$D21,H$4<=$E21),1,"") | I21: =IF(AND(I$4>=$D21,I$4<=$E21),1,"") | J21: =IF(AND(J$4>=$D21,J$4<=$E21),1,"") -> 1 | K21: =IF(AND(K$4>=$D21,K$4<=$E21),1,"") -> 1 | L21: =IF(AND(L$4>=$D21,L$4<=$E21),1,"") -> 1 | M21: =IF(AND(M$4>=$D21,M$4<=$E21),1,"") | ... AE21: =IF(AND(AE$4>=$D21,AE$4<=$E21),1,"")
A22: =Features!A16 -> B2 | B22: =Features!C16 -> Re-ingest KB with hybrid + metadata filters | C22: =Features!E16 -> MVP | D22: =Features!I16 -> 5 | E22: =Features!J16 -> 8 | F22: =IF(AND(F$4>=$D22,F$4<=$E22),1,"") | G22: =IF(AND(G$4>=$D22,G$4<=$E22),1,"") | H22: =IF(AND(H$4>=$D22,H$4<=$E22),1,"") | I22: =IF(AND(I$4>=$D22,I$4<=$E22),1,"") | J22: =IF(AND(J$4>=$D22,J$4<=$E22),1,"") -> 1 | K22: =IF(AND(K$4>=$D22,K$4<=$E22),1,"") -> 1 | L22: =IF(AND(L$4>=$D22,L$4<=$E22),1,"") -> 1 | M22: =IF(AND(M$4>=$D22,M$4<=$E22),1,"") -> 1 | ... AE22: =IF(AND(AE$4>=$D22,AE$4<=$E22),1,"")
A23: =Features!A17 -> B3 | B23: =Features!C17 -> EDMX live run (XSUAA auth) | C23: =Features!E17 -> R2 | D23: =Features!I17 -> 9 | E23: =Features!J17 -> 12 | F23: =IF(AND(F$4>=$D23,F$4<=$E23),1,"") | G23: =IF(AND(G$4>=$D23,G$4<=$E23),1,"") | H23: =IF(AND(H$4>=$D23,H$4<=$E23),1,"") | I23: =IF(AND(I$4>=$D23,I$4<=$E23),1,"") | J23: =IF(AND(J$4>=$D23,J$4<=$E23),1,"") | K23: =IF(AND(K$4>=$D23,K$4<=$E23),1,"") | L23: =IF(AND(L$4>=$D23,L$4<=$E23),1,"") | M23: =IF(AND(M$4>=$D23,M$4<=$E23),1,"") | ... AE23: =IF(AND(AE$4>=$D23,AE$4<=$E23),1,"")
A24: =Features!A18 -> B4 | B24: =Features!C18 -> help-portal-cds re-crawl | C24: =Features!E18 -> R2 | D24: =Features!I18 -> 10 | E24: =Features!J18 -> 13 | F24: =IF(AND(F$4>=$D24,F$4<=$E24),1,"") | G24: =IF(AND(G$4>=$D24,G$4<=$E24),1,"") | H24: =IF(AND(H$4>=$D24,H$4<=$E24),1,"") | I24: =IF(AND(I$4>=$D24,I$4<=$E24),1,"") | J24: =IF(AND(J$4>=$D24,J$4<=$E24),1,"") | K24: =IF(AND(K$4>=$D24,K$4<=$E24),1,"") | L24: =IF(AND(L$4>=$D24,L$4<=$E24),1,"") | M24: =IF(AND(M$4>=$D24,M$4<=$E24),1,"") | ... AE24: =IF(AND(AE$4>=$D24,AE$4<=$E24),1,"")
A25: =Features!A19 -> B5 | B25: =Features!C19 -> KB coverage gap closure | C25: =Features!E19 -> R2 | D25: =Features!I19 -> 11 | E25: =Features!J19 -> 14 | F25: =IF(AND(F$4>=$D25,F$4<=$E25),1,"") | G25: =IF(AND(G$4>=$D25,G$4<=$E25),1,"") | H25: =IF(AND(H$4>=$D25,H$4<=$E25),1,"") | I25: =IF(AND(I$4>=$D25,I$4<=$E25),1,"") | J25: =IF(AND(J$4>=$D25,J$4<=$E25),1,"") | K25: =IF(AND(K$4>=$D25,K$4<=$E25),1,"") | L25: =IF(AND(L$4>=$D25,L$4<=$E25),1,"") | M25: =IF(AND(M$4>=$D25,M$4<=$E25),1,"") | ... AE25: =IF(AND(AE$4>=$D25,AE$4<=$E25),1,"")
A26: =Features!A20 -> B6 | B26: =Features!C20 -> LearningPortalFetcher | C26: =Features!E20 -> R3 | D26: =Features!I20 -> 17 | E26: =Features!J20 -> 19 | F26: =IF(AND(F$4>=$D26,F$4<=$E26),1,"") | G26: =IF(AND(G$4>=$D26,G$4<=$E26),1,"") | H26: =IF(AND(H$4>=$D26,H$4<=$E26),1,"") | I26: =IF(AND(I$4>=$D26,I$4<=$E26),1,"") | J26: =IF(AND(J$4>=$D26,J$4<=$E26),1,"") | K26: =IF(AND(K$4>=$D26,K$4<=$E26),1,"") | L26: =IF(AND(L$4>=$D26,L$4<=$E26),1,"") | M26: =IF(AND(M$4>=$D26,M$4<=$E26),1,"") | ... AE26: =IF(AND(AE$4>=$D26,AE$4<=$E26),1,"")
A27: =Features!A21 -> B7 | B27: =Features!C21 -> Blob raw cache + ingest versioning | C27: =Features!E21 -> R2 | D27: =Features!I21 -> 9 | E27: =Features!J21 -> 11 | F27: =IF(AND(F$4>=$D27,F$4<=$E27),1,"") | G27: =IF(AND(G$4>=$D27,G$4<=$E27),1,"") | H27: =IF(AND(H$4>=$D27,H$4<=$E27),1,"") | I27: =IF(AND(I$4>=$D27,I$4<=$E27),1,"") | J27: =IF(AND(J$4>=$D27,J$4<=$E27),1,"") | K27: =IF(AND(K$4>=$D27,K$4<=$E27),1,"") | L27: =IF(AND(L$4>=$D27,L$4<=$E27),1,"") | M27: =IF(AND(M$4>=$D27,M$4<=$E27),1,"") | ... AE27: =IF(AND(AE$4>=$D27,AE$4<=$E27),1,"")
A28: =Features!A22 -> B8 | B28: =Features!C22 -> Retrieval quality eval harness | C28: =Features!E22 -> MVP | D28: =Features!I22 -> 6 | E28: =Features!J22 -> 8 | F28: =IF(AND(F$4>=$D28,F$4<=$E28),1,"") | G28: =IF(AND(G$4>=$D28,G$4<=$E28),1,"") | H28: =IF(AND(H$4>=$D28,H$4<=$E28),1,"") | I28: =IF(AND(I$4>=$D28,I$4<=$E28),1,"") | J28: =IF(AND(J$4>=$D28,J$4<=$E28),1,"") | K28: =IF(AND(K$4>=$D28,K$4<=$E28),1,"") -> 1 | L28: =IF(AND(L$4>=$D28,L$4<=$E28),1,"") -> 1 | M28: =IF(AND(M$4>=$D28,M$4<=$E28),1,"") -> 1 | ... AE28: =IF(AND(AE$4>=$D28,AE$4<=$E28),1,"")
A29: MCP Server
A30: =Features!A24 -> C2 | B30: =Features!C24 -> MCP HTTP/SSE transport + auth middleware | C30: =Features!E24 -> MVP | D30: =Features!I24 -> 3 | E30: =Features!J24 -> 5 | F30: =IF(AND(F$4>=$D30,F$4<=$E30),1,"") | G30: =IF(AND(G$4>=$D30,G$4<=$E30),1,"") | H30: =IF(AND(H$4>=$D30,H$4<=$E30),1,"") -> 1 | I30: =IF(AND(I$4>=$D30,I$4<=$E30),1,"") -> 1 | J30: =IF(AND(J$4>=$D30,J$4<=$E30),1,"") -> 1 | K30: =IF(AND(K$4>=$D30,K$4<=$E30),1,"") | L30: =IF(AND(L$4>=$D30,L$4<=$E30),1,"") | M30: =IF(AND(M$4>=$D30,M$4<=$E30),1,"") | ... AE30: =IF(AND(AE$4>=$D30,AE$4<=$E30),1,"")
A31: =Features!A25 -> C3 | B31: =Features!C25 -> MCP uses managed identity for Search | C31: =Features!E25 -> MVP | D31: =Features!I25 -> 5 | E31: =Features!J25 -> 6 | F31: =IF(AND(F$4>=$D31,F$4<=$E31),1,"") | G31: =IF(AND(G$4>=$D31,G$4<=$E31),1,"") | H31: =IF(AND(H$4>=$D31,H$4<=$E31),1,"") | I31: =IF(AND(I$4>=$D31,I$4<=$E31),1,"") | J31: =IF(AND(J$4>=$D31,J$4<=$E31),1,"") -> 1 | K31: =IF(AND(K$4>=$D31,K$4<=$E31),1,"") -> 1 | L31: =IF(AND(L$4>=$D31,L$4<=$E31),1,"") | M31: =IF(AND(M$4>=$D31,M$4<=$E31),1,"") | ... AE31: =IF(AND(AE$4>=$D31,AE$4<=$E31),1,"")
A32: =Features!A26 -> C4 | B32: =Features!C26 -> New MCP tools | C32: =Features!E26 -> R2 | D32: =Features!I26 -> 12 | E32: =Features!J26 -> 14 | F32: =IF(AND(F$4>=$D32,F$4<=$E32),1,"") | G32: =IF(AND(G$4>=$D32,G$4<=$E32),1,"") | H32: =IF(AND(H$4>=$D32,H$4<=$E32),1,"") | I32: =IF(AND(I$4>=$D32,I$4<=$E32),1,"") | J32: =IF(AND(J$4>=$D32,J$4<=$E32),1,"") | K32: =IF(AND(K$4>=$D32,K$4<=$E32),1,"") | L32: =IF(AND(L$4>=$D32,L$4<=$E32),1,"") | M32: =IF(AND(M$4>=$D32,M$4<=$E32),1,"") | ... AE32: =IF(AND(AE$4>=$D32,AE$4<=$E32),1,"")
A33: =Features!A27 -> C5 | B33: =Features!C27 -> MCP rate limits, audit logs, tenant filters | C33: =Features!E27 -> R2 | D33: =Features!I27 -> 13 | E33: =Features!J27 -> 14 | F33: =IF(AND(F$4>=$D33,F$4<=$E33),1,"") | G33: =IF(AND(G$4>=$D33,G$4<=$E33),1,"") | H33: =IF(AND(H$4>=$D33,H$4<=$E33),1,"") | I33: =IF(AND(I$4>=$D33,I$4<=$E33),1,"") | J33: =IF(AND(J$4>=$D33,J$4<=$E33),1,"") | K33: =IF(AND(K$4>=$D33,K$4<=$E33),1,"") | L33: =IF(AND(L$4>=$D33,L$4<=$E33),1,"") | M33: =IF(AND(M$4>=$D33,M$4<=$E33),1,"") | ... AE33: =IF(AND(AE$4>=$D33,AE$4<=$E33),1,"")
A34: Agents & Pipeline
A35: =Features!A32 -> D5 | B35: =Features!C32 -> Headless agent service on Azure | C35: =Features!E32 -> R2 | D35: =Features!I32 -> 9 | E35: =Features!J32 -> 14 | F35: =IF(AND(F$4>=$D35,F$4<=$E35),1,"") | G35: =IF(AND(G$4>=$D35,G$4<=$E35),1,"") | H35: =IF(AND(H$4>=$D35,H$4<=$E35),1,"") | I35: =IF(AND(I$4>=$D35,I$4<=$E35),1,"") | J35: =IF(AND(J$4>=$D35,J$4<=$E35),1,"") | K35: =IF(AND(K$4>=$D35,K$4<=$E35),1,"") | L35: =IF(AND(L$4>=$D35,L$4<=$E35),1,"") | M35: =IF(AND(M$4>=$D35,M$4<=$E35),1,"") | ... AE35: =IF(AND(AE$4>=$D35,AE$4<=$E35),1,"")
A36: =Features!A33 -> D6 | B36: =Features!C33 -> LLM proxy on Azure | C36: =Features!E33 -> MVP | D36: =Features!I33 -> 4 | E36: =Features!J33 -> 7 | F36: =IF(AND(F$4>=$D36,F$4<=$E36),1,"") | G36: =IF(AND(G$4>=$D36,G$4<=$E36),1,"") | H36: =IF(AND(H$4>=$D36,H$4<=$E36),1,"") | I36: =IF(AND(I$4>=$D36,I$4<=$E36),1,"") -> 1 | J36: =IF(AND(J$4>=$D36,J$4<=$E36),1,"") -> 1 | K36: =IF(AND(K$4>=$D36,K$4<=$E36),1,"") -> 1 | L36: =IF(AND(L$4>=$D36,L$4<=$E36),1,"") -> 1 | M36: =IF(AND(M$4>=$D36,M$4<=$E36),1,"") | ... AE36: =IF(AND(AE$4>=$D36,AE$4<=$E36),1,"")
A37: =Features!A34 -> D7 | B37: =Features!C34 -> Clean Core validation loop | C37: =Features!E34 -> R2 | D37: =Features!I34 -> 9 | E37: =Features!J34 -> 13 | F37: =IF(AND(F$4>=$D37,F$4<=$E37),1,"") | G37: =IF(AND(G$4>=$D37,G$4<=$E37),1,"") | H37: =IF(AND(H$4>=$D37,H$4<=$E37),1,"") | I37: =IF(AND(I$4>=$D37,I$4<=$E37),1,"") | J37: =IF(AND(J$4>=$D37,J$4<=$E37),1,"") | K37: =IF(AND(K$4>=$D37,K$4<=$E37),1,"") | L37: =IF(AND(L$4>=$D37,L$4<=$E37),1,"") | M37: =IF(AND(M$4>=$D37,M$4<=$E37),1,"") | ... AE37: =IF(AND(AE$4>=$D37,AE$4<=$E37),1,"")
A38: =Features!A35 -> D8 | B38: =Features!C35 -> Source citations in generated output | C38: =Features!E35 -> R2 | D38: =Features!I35 -> 12 | E38: =Features!J35 -> 14 | F38: =IF(AND(F$4>=$D38,F$4<=$E38),1,"") | G38: =IF(AND(G$4>=$D38,G$4<=$E38),1,"") | H38: =IF(AND(H$4>=$D38,H$4<=$E38),1,"") | I38: =IF(AND(I$4>=$D38,I$4<=$E38),1,"") | J38: =IF(AND(J$4>=$D38,J$4<=$E38),1,"") | K38: =IF(AND(K$4>=$D38,K$4<=$E38),1,"") | L38: =IF(AND(L$4>=$D38,L$4<=$E38),1,"") | M38: =IF(AND(M$4>=$D38,M$4<=$E38),1,"") | ... AE38: =IF(AND(AE$4>=$D38,AE$4<=$E38),1,"")
A39: =Features!A36 -> D9 | B39: =Features!C36 -> Agent marketplace (Sprint 7) | C39: =Features!E36 -> R3 | D39: =Features!I36 -> 15 | E39: =Features!J36 -> 20 | F39: =IF(AND(F$4>=$D39,F$4<=$E39),1,"") | G39: =IF(AND(G$4>=$D39,G$4<=$E39),1,"") | H39: =IF(AND(H$4>=$D39,H$4<=$E39),1,"") | I39: =IF(AND(I$4>=$D39,I$4<=$E39),1,"") | J39: =IF(AND(J$4>=$D39,J$4<=$E39),1,"") | K39: =IF(AND(K$4>=$D39,K$4<=$E39),1,"") | L39: =IF(AND(L$4>=$D39,L$4<=$E39),1,"") | M39: =IF(AND(M$4>=$D39,M$4<=$E39),1,"") | ... AE39: =IF(AND(AE$4>=$D39,AE$4<=$E39),1,"")
A40: =Features!A37 -> D10 | B40: =Features!C37 -> Multi-model routing | C40: =Features!E37 -> R3 | D40: =Features!I37 -> 14 | E40: =Features!J37 -> 17 | F40: =IF(AND(F$4>=$D40,F$4<=$E40),1,"") | G40: =IF(AND(G$4>=$D40,G$4<=$E40),1,"") | H40: =IF(AND(H$4>=$D40,H$4<=$E40),1,"") | I40: =IF(AND(I$4>=$D40,I$4<=$E40),1,"") | J40: =IF(AND(J$4>=$D40,J$4<=$E40),1,"") | K40: =IF(AND(K$4>=$D40,K$4<=$E40),1,"") | L40: =IF(AND(L$4>=$D40,L$4<=$E40),1,"") | M40: =IF(AND(M$4>=$D40,M$4<=$E40),1,"") | ... AE40: =IF(AND(AE$4>=$D40,AE$4<=$E40),1,"")
A41: =Features!A38 -> D11 | B41: =Features!C38 -> Prompt registry + eval regression suite | C41: =Features!E38 -> R3 | D41: =Features!I38 -> 16 | E41: =Features!J38 -> 19 | F41: =IF(AND(F$4>=$D41,F$4<=$E41),1,"") | G41: =IF(AND(G$4>=$D41,G$4<=$E41),1,"") | H41: =IF(AND(H$4>=$D41,H$4<=$E41),1,"") | I41: =IF(AND(I$4>=$D41,I$4<=$E41),1,"") | J41: =IF(AND(J$4>=$D41,J$4<=$E41),1,"") | K41: =IF(AND(K$4>=$D41,K$4<=$E41),1,"") | L41: =IF(AND(L$4>=$D41,L$4<=$E41),1,"") | M41: =IF(AND(M$4>=$D41,M$4<=$E41),1,"") | ... AE41: =IF(AND(AE$4>=$D41,AE$4<=$E41),1,"")
...

Sheet Release Plan
A1: Release plan - when each feature goes live
A2: Release weeks are the source of truth; each Planned feature must finish by its release week.
A4: Release | B4: Name | C4: Week | D4: Go-live date (Fri) | E4: Environment | F4: New features | G4: Go/no-go criteria
A5: R0 | B5: R0 - Azure Foundations (dev env live) | C5: 4 | D5: =Summary!$C$4+7*(C5-1)+4 -> 46346 | E5: Azure dev | F5: =COUNTIFS(Features!$E$2:$E$72,A5,Features!$H$2:$H$72,"Planned") -> 7 | G5: IaC reproducible; CI/CD green; MCP + LLM proxy reachable in dev; KB in index v2; contract drafted
A6: MVP | B6: MVP - DarkHorse on Azure, Continuum read integration, internal pilot | C6: 8 | D6: =Summary!$C$4+7*(C6-1)+4 -> 46374 | E6: Azure prod (internal pilot) | F6: =COUNTIFS(Features!$E$2:$E$72,A6,Features!$H$2:$H$72,"Planned") -> 16 | G6: Entra auth enforced; retrieval eval above agreed threshold; one real RICEFW end to end; rollback tested; budgets/alerts live
A7: R2 | B7: R2 - Memory, Clean Core loop, full Continuum + ChickletFlow integration | C7: 14 | D7: =Summary!$C$4+7*(C7-1)+4 -> 46416 | E7: Azure prod (pilot teams) | F7: =COUNTIFS(Features!$E$2:$E$72,A7,Features!$H$2:$H$72,"Planned") -> 24 | G7: Clean Core loop pass-rate target met; Continuum webhook -> run -> push-back -> ChickletFlow status works; auth on all three apps
A8: R3 | B8: R3 - Marketplace, multi-model, private networking, dashboards | C8: 20 | D8: =Summary!$C$4+7*(C8-1)+4 -> 46458 | E8: Azure prod (all programs) | F8: =COUNTIFS(Features!$E$2:$E$72,A8,Features!$H$2:$H$72,"Planned") -> 11 | G8: UAT across 5+ RICEFW types; private networking validated; marketplace install/update works
A9: GA | B9: GA - Production hardening, client-tenant template, security sign-off | C9: 24 | D9: =Summary!$C$4+7*(C9-1)+4 -> 46486 | E9: Azure prod + client-tenant template | F9: =COUNTIFS(Features!$E$2:$E$72,A9,Features!$H$2:$H$72,"Planned") -> 6 | G9: Pen-test findings closed; DR test passed; docs + training done; support model and SLA agreed
A11: Features by release
A12: Release | B12: Feature | C12: ID | D12: Go-live date | E12: Workstream | F12: MVP? | G12: Priority
A13: Shipped | B13: Ingest framework + 8 fetchers + Azure embedder/index | C13: B0 | D13: Live (v0.7.38) | E13: RAG & Knowledge | G13: High
A14: Shipped | B14: MCP tools (verify_badi/exit, clean core level, CDS, EML, RAP, CBO) | C14: C1 | D14: Live (v0.7.38) | E14: MCP Server | G14: High
A15: Shipped | B15: Grounded Code/TDS/SO/FDS agents | C15: D1 | D15: Live (v0.7.38) | E15: Agents & Pipeline | G15: High
A16: Shipped | B16: ReviewAgent + auto-rewrite + ZI_ wrappers | C16: D2 | D16: Live (v0.7.38) | E16: Agents & Pipeline | G16: High
A17: Shipped | B17: TdsPostCodeAgent | C17: D3 | D17: Live (v0.7.38) | E17: Agents & Pipeline | G17: Med
A18: Shipped | B18: Solution architecture diagram | C18: D4 | D18: Live (v0.7.38) | E18: Agents & Pipeline | G18: Med
A19: Shipped | B19: Extension v0.7.38 + version in status bar | C19: F2 | D19: Live (v0.7.38) | E19: Editor | G19: Low
A20: R0 | B20: Azure landing zone + IaC | C20: A1 | D20: =Summary!$C$4+7*(4-1)+4 -> 46346 | E20: Azure Platform | F20: Yes | G20: High
A21: R0 | B21: Azure OpenAI / Foundry deployments | C21: A2 | D21: =Summary!$C$4+7*(4-1)+4 -> 46346 | E21: Azure Platform | F21: Yes | G21: High
A22: R0 | B22: Azure AI Search + index schema v2 | C22: A3 | D22: =Summary!$C$4+7*(4-1)+4 -> 46346 | E22: Azure Platform | F22: Yes | G22: High
A23: R0 | B23: Containerize services | C23: A4 | D23: =Summary!$C$4+7*(4-1)+4 -> 46346 | E23: Azure Platform | F23: Yes | G23: High
A24: R0 | B24: CI/CD pipelines | C24: A7 | D24: =Summary!$C$4+7*(4-1)+4 -> 46346 | E24: Azure Platform | F24: Yes | G24: High
A25: R0 | B25: Event and ID contract | C25: I2 | D25: =Summary!$C$4+7*(4-1)+4 -> 46346 | E25: Cross-Product | F25: Yes | G25: High
A26: R0 | B26: Threat model + security design review | C26: J1 | D26: =Summary!$C$4+7*(4-1)+4 -> 46346 | E26: Release & Governance | F26: Yes | G26: High
A27: MVP | B27: Container Apps env + APIM + Front Door | C27: A5 | D27: =Summary!$C$4+7*(8-1)+4 -> 46374 | E27: Azure Platform | F27: Yes | G27: High
A28: MVP | B28: Entra ID auth + managed identity | C28: A6 | D28: =Summary!$C$4+7*(8-1)+4 -> 46374 | E28: Azure Platform | F28: Yes | G28: High
A29: MVP | B29: Observability + cost controls | C29: A8 | D29: =Summary!$C$4+7*(8-1)+4 -> 46374 | E29: Azure Platform | F29: Yes | G29: Med
A30: MVP | B30: Prod environment + go-live runbook | C30: A9 | D30: =Summary!$C$4+7*(8-1)+4 -> 46374 | E30: Azure Platform | F30: Yes | G30: High
A31: MVP | B31: Scheduled ingest job on Azure | C31: B1 | D31: =Summary!$C$4+7*(8-1)+4 -> 46374 | E31: RAG & Knowledge | F31: Yes | G31: High
A32: MVP | B32: Re-ingest KB with hybrid + metadata filters | C32: B2 | D32: =Summary!$C$4+7*(8-1)+4 -> 46374 | E32: RAG & Knowledge | F32: Yes | G32: High
A33: MVP | B33: Retrieval quality eval harness | C33: B8 | D33: =Summary!$C$4+7*(8-1)+4 -> 46374 | E33: RAG & Knowledge | F33: Yes | G33: High
A34: MVP | B34: MCP HTTP/SSE transport + auth middleware | C34: C2 | D34: =Summary!$C$4+7*(8-1)+4 -> 46374 | E34: MCP Server | F34: Yes | G34: High
A35: MVP | B35: MCP uses managed identity for Search | C35: C3 | D35: =Summary!$C$4+7*(8-1)+4 -> 46374 | E35: MCP Server | F35: Yes | G35: High
A36: MVP | B36: LLM proxy on Azure | C36: D6 | D36: =Summary!$C$4+7*(8-1)+4 -> 46374 | E36: Agents & Pipeline | F36: Yes | G36: High
A37: MVP | B37: Editor endpoint config + Entra sign-in | C37: F1 | D37: =Summary!$C$4+7*(8-1)+4 -> 46374 | E37: Editor | F37: Yes | G37: High
A38: MVP | B38: Pipeline UX for Azure status/errors | C38: F3 | D38: =Summary!$C$4+7*(8-1)+4 -> 46374 | E38: Editor | F38: Yes | G38: Med
... A42: MVP | B42: Internal pilot on one RICEFW | C42: I4 | D42: =Summary!$C$4+7*(8-1)+4 -> 46374 | E42: Cross-Product | F42: Yes | G42: High
A43: R2 | B43: EDMX live run (XSUAA auth) | C43: B3 | D43: =Summary!$C$4+7*(14-1)+4 -> 46416 | E43: RAG & Knowledge | G43: High
A44: R2 | B44: help-portal-cds re-crawl | C44: B4 | D44: =Summary!$C$4+7*(14-1)+4 -> 46416 | E44: RAG & Knowledge | G44: Med
A45: R2 | B45: KB coverage gap closure | C45: B5 | D45: =Summary!$C$4+7*(14-1)+4 -> 46416 | E45: RAG & Knowledge | G45: High
...

Sheet Integration
A1: System | B1: Area | C1: Type | D1: Change required | E1: Where (code) | F1: Release | G1: Start wk | H1: End wk | I1: Start date | J1: End date | K1: Person-weeks | L1: Owner
A2: Continuum | B2: Auth | C2: API | D2: Add service-token (API key / Entra client-credential) auth alongside NextAuth sessions so DarkHorse can call ricefw endpoints | E2: lib/auth.ts, middleware.ts, app/api/w/[slug]/ricefws/* | F2: MVP | G2: 3 | H2: 6 | I2: =Summary!$C$4+7*(G2-1) -> 46335 | J2: =Summary!$C$4+7*(H2-1)+4 -> 46360 | K2: 3 | L2: TBD
A3: Continuum | B3: API contract | C3: API | D3: Publish OpenAPI spec for read of latest APPROVED RicefwVersion sections (BR, FD, TD, Test, Cutover) by workspace slug + objectId | E3: app/api/w/[slug]/ricefws/[id]/route.ts | F3: MVP | G3: 3 | H3: 6 | I3: =Summary!$C$4+7*(G3-1) -> 46335 | J3: =Summary!$C$4+7*(H3-1)+4 -> 46360 | K3: 1 | L3: TBD
A4: Continuum | B4: Schema | C4: Data model | D4: Add darkhorseRunId, cleanCoreScore, generatedObjects (JSON) to Ricefw/RicefwVersion; add DARKHORSE to TraceSystem enum; Prisma migration | E4: prisma/schema.prisma (Ricefw, TraceLink, TraceSystem) | F4: R2 | G4: 9 | H4: 11 | I4: =Summary!$C$4+7*(G4-1) -> 46377 | J4: =Summary!$C$4+7*(H4-1)+4 -> 46395 | K4: 2 | L4: TBD
A5: Continuum | B5: Write-back | C5: API | D5: Endpoint to create DRAFT version from DarkHorse and attach generated TDS/code/diagram/Clean Core report as Attachments | E5: app/api/w/[slug]/ricefws/[id]/attachments, versions | F5: R2 | G5: 9 | H5: 12 | I5: =Summary!$C$4+7*(G5-1) -> 46377 | J5: =Summary!$C$4+7*(H5-1)+4 -> 46402 | K5: 3 | L5: TBD
A6: Continuum | B6: Webhook | C6: API | D6: Emit signed webhook on approval (APPROVED/PUBLISHED) to DarkHorse agent service; retry + dead-letter | E6: app/api/w/[slug]/ricefws/[id]/approvals/route.ts, status/route.ts | F6: R2 | G6: 11 | H6: 14 | I6: =Summary!$C$4+7*(G6-1) -> 46391 | J6: =Summary!$C$4+7*(H6-1)+4 -> 46416 | K6: 3 | L6: TBD
A7: Continuum | B7: Identity | C7: Auth | D7: Replace credentials/invite-only auth with Entra ID SSO; map Entra groups to WorkspaceRole | E7: app/api/auth/[...nextauth], lib/auth.ts | F7: R2 | G7: 7 | H7: 11 | I7: =Summary!$C$4+7*(G7-1) -> 46363 | J7: =Summary!$C$4+7*(H7-1)+4 -> 46395 | K7: 3 | L7: TBD
A8: Continuum | B8: AI | C8: Code | D8: Route lib/ai (enhanceField) through the Azure LLM proxy instead of direct ANTHROPIC_API_KEY | E8: lib/ai.ts, app/api/w/[slug]/ai/enhance/route.ts | F8: R2 | G8: 10 | H8: 12 | I8: =Summary!$C$4+7*(G8-1) -> 46384 | J8: =Summary!$C$4+7*(H8-1)+4 -> 46402 | K8: 2 | L8: TBD
A9: Continuum | B9: Deploy | C9: Infra | D9: Container Apps + Azure Postgres Flexible Server; Key Vault for AUTH_SECRET; run prisma migrate deploy in release pipeline | E9: Dockerfile, docker-compose.yml | F9: R2 | G9: 7 | H9: 11 | I9: =Summary!$C$4+7*(G9-1) -> 46363 | J9: =Summary!$C$4+7*(H9-1)+4 -> 46395 | K9: 4 | L9: TBD
A10: Continuum | B10: UI | C10: UI | D10: Generate with DarkHorse button, run status panel, Clean Core score badge on RICEFW page | E10: components/*, app/w/[slug]/... | F10: R3 | G10: 14 | H10: 18 | I10: =Summary!$C$4+7*(G10-1) -> 46412 | J10: =Summary!$C$4+7*(H10-1)+4 -> 46444 | K10: 4 | L10: TBD
A11: ChickletFlow | B11: Auth | C11: Auth | D11: Add Entra ID auth + service tokens to FastAPI and /ws/board (currently open; CORS only) | E11: backend/app/main.py, config.py, websocket.py | F11: R2 | G11: 6 | H11: 9 | I11: =Summary!$C$4+7*(G11-1) -> 46356 | J11: =Summary!$C$4+7*(H11-1)+4 -> 46381 | K11: 3 | L11: TBD
A12: ChickletFlow | B12: Schema | C12: Data model | D12: Add continuum_object_id, continuum_url, darkhorse_run_id, clean_core_score to work_items; Alembic migration | E12: backend/app/models.py, schemas.py, alembic/ | F12: R2 | G12: 8 | H12: 10 | I12: =Summary!$C$4+7*(G12-1) -> 46370 | J12: =Summary!$C$4+7*(H12-1)+4 -> 46388 | K12: 2 | L12: TBD
A13: ChickletFlow | B13: Events | C13: API | D13: POST /api/work-items/{id}/events for DarkHorse/Continuum; add source column to status_history; broadcast over WebSocket | E13: backend/app/routers/work_items.py, crud.py, websocket.py | F13: R2 | G13: 9 | H13: 12 | I13: =Summary!$C$4+7*(G13-1) -> 46377 | J13: =Summary!$C$4+7*(H13-1)+4 -> 46402 | K13: 3 | L13: TBD
... A21: All | B21: Contract | C21: Design | D21: Shared event/ID contract and versioning (RICEFW ID, run id, status events) | E21: docs/ (new integration spec) | F21: R0 | G21: 2 | H21: 4 | I21: =Summary!$C$4+7*(G21-1) -> 46328 | J21: =Summary!$C$4+7*(H21-1)+4 -> 46346 | K21: 2 | L21: TBD

Sheet Azure Deployment
A1: Step | B1: Phase | C1: What gets deployed | D1: Features | E1: Start wk | F1: End wk | G1: Start date | H1: End date | I1: Environment
A2: 1 | B2: Foundation | C2: Subscription, RBAC, naming/tagging, resource groups dev/prod, Key Vault, ACR, Log Analytics | D2: A1, J1 | E2: 1 | F2: 3 | G2: =Summary!$C$4+7*(E2-1) -> 46321 | H2: =Summary!$C$4+7*(F2-1)+4 -> 46339 | I2: Dev
A3: 2 | B3: AI services | C3: Azure OpenAI chat + embeddings deployments, AI Search S1 + semantic ranker | D3: A2, A3 | E3: 1 | F3: 4 | G3: =Summary!$C$4+7*(E3-1) -> 46321 | H3: =Summary!$C$4+7*(F3-1)+4 -> 46346 | I3: Dev
A4: 3 | B4: Containers + CI/CD | C4: Dockerfiles, ACR push, Container Apps env, GitHub Actions | D4: A4, A7 | E4: 3 | F4: 4 | G4: =Summary!$C$4+7*(E4-1) -> 46335 | H4: =Summary!$C$4+7*(F4-1)+4 -> 46346 | I4: Dev
A5: 4 | B5: Dev live (R0) | C5: MCP + LLM proxy reachable in dev; KB ingested to index v2 | D5: M1 | E5: 4 | F5: 4 | G5: =Summary!$C$4+7*(E5-1) -> 46342 | H5: =Summary!$C$4+7*(F5-1)+4 -> 46346 | I5: Dev
A6: 5 | B6: Edge + identity | C6: APIM, Front Door, Entra app registration, managed identities | D6: A5, A6 | E6: 4 | F6: 7 | G6: =Summary!$C$4+7*(E6-1) -> 46342 | H6: =Summary!$C$4+7*(F6-1)+4 -> 46367 | I6: Dev -> Prod
A7: 6 | B7: Ingest + retrieval | C7: Scheduled ingest job, hybrid index, eval harness | D7: B1, B2, B8 | E7: 5 | F7: 8 | G7: =Summary!$C$4+7*(E7-1) -> 46349 | H7: =Summary!$C$4+7*(F7-1)+4 -> 46374 | I7: Dev -> Prod
A8: 7 | B8: Observability | C8: App Insights, dashboards, alerts, budgets | D8: A8 | E8: 6 | F8: 8 | G8: =Summary!$C$4+7*(E8-1) -> 46356 | H8: =Summary!$C$4+7*(F8-1)+4 -> 46374 | I8: Dev -> Prod
A9: 8 | B9: Prod + MVP go-live | C9: Prod env, runbook, smoke tests, pilot RICEFW | D9: A9, I4 | E9: 7 | F9: 8 | G9: =Summary!$C$4+7*(E9-1) -> 46363 | H9: =Summary!$C$4+7*(F9-1)+4 -> 46374 | I9: Prod
A10: 9 | B10: Continuum + ChickletFlow to Azure | C10: Container Apps + Postgres Flexible for both apps; Entra SSO | D10: G6, H6, H1 | E10: 6 | F10: 11 | G10: =Summary!$C$4+7*(E10-1) -> 46356 | H10: =Summary!$C$4+7*(F10-1)+4 -> 46395 | I10: Dev -> Prod
A11: 10 | B11: Memory + agent service | C11: Cosmos DB, headless agent service, MCP memory tools | D11: E1, D5 | E11: 8 | F11: 14 | G11: =Summary!$C$4+7*(E11-1) -> 46370 | H11: =Summary!$C$4+7*(F11-1)+4 -> 46416 | I11: Prod
A12: 11 | B12: Private networking | C12: VNet, Private Endpoints, optional no-public-access | D12: A10 | E12: 16 | F12: 20 | G12: =Summary!$C$4+7*(E12-1) -> 46426 | H12: =Summary!$C$4+7*(F12-1)+4 -> 46458 | I12: Prod
A13: 12 | B13: Client-tenant template + DR | C13: Parameterized IaC for client subscriptions, DR test, pen-test fixes | D13: A11, A12 | E13: 20 | F13: 24 | G13: =Summary!$C$4+7*(E13-1) -> 46454 | H13: =Summary!$C$4+7*(F13-1)+4 -> 46486 | I13: Prod / Client
B15: Key Azure dates
B16: Dev environment live | C16: Week 4 | G16: =Summary!$C$4+7*(4-1)+4 -> 46346
B17: Prod environment + MVP go-live | C17: Week 8 | G17: =Summary!$C$4+7*(8-1)+4 -> 46374
B18: Continuum + ChickletFlow on Azure | C18: Week 11 | G18: =Summary!$C$4+7*(11-1)+4 -> 46395
B19: Integrated release (R2) | C19: Week 14 | G19: =Summary!$C$4+7*(14-1)+4 -> 46416
B20: Private networking done | C20: Week 20 | G20: =Summary!$C$4+7*(20-1)+4 -> 46458
B21: GA / client-tenant template | C21: Week 24 | G21: =Summary!$C$4+7*(24-1)+4 -> 46486

Sheet Effort by Workstream
A1: Workstream | B1: R0 | C1: MVP | D1: R2 | E1: R3 | F1: GA | G1: Total (pw)
A2: Azure Platform | B2: =SUMIFS(Features!$M$2:$M$72,Features!$B$2:$B$72,$A2,Features!$E$2:$E$72,B$1) -> 10 | C2: =SUMIFS(Features!$M$2:$M$72,Features!$B$2:$B$72,$A2,Features!$E$2:$E$72,C$1) -> 10 | D2: =SUMIFS(Features!$M$2:$M$72,Features!$B$2:$B$72,$A2,Features!$E$2:$E$72,D$1) -> 0 | E2: =SUMIFS(Features!$M$2:$M$72,Features!$B$2:$B$72,$A2,Features!$E$2:$E$72,E$1) -> 4 | F2: =SUMIFS(Features!$M$2:$M$72,Features!$B$2:$B$72,$A2,Features!$E$2:$E$72,F$1) -> 7 | G2: =SUM(B2:F2) -> 31
A3: RAG & Knowledge | B3: =SUMIFS(Features!$M$2:$M$72,Features!$B$2:$B$72,$A3,Features!$E$2:$E$72,B$1) -> 0 | C3: =SUMIFS(Features!$M$2:$M$72,Features!$B$2:$B$72,$A3,Features!$E$2:$E$72,C$1) -> 7 | D3: =SUMIFS(Features!$M$2:$M$72,Features!$B$2:$B$72,$A3,Features!$E$2:$E$72,D$1) -> 10 | E3: =SUMIFS(Features!$M$2:$M$72,Features!$B$2:$B$72,$A3,Features!$E$2:$E$72,E$1) -> 1 | F3: =SUMIFS(Features!$M$2:$M$72,Features!$B$2:$B$72,$A3,Features!$E$2:$E$72,F$1) -> 0 | G3: =SUM(B3:F3) -> 18
A4: MCP Server | B4: =SUMIFS(Features!$M$2:$M$72,Features!$B$2:$B$72,$A4,Features!$E$2:$E$72,B$1) -> 0 | C4: =SUMIFS(Features!$M$2:$M$72,Features!$B$2:$B$72,$A4,Features!$E$2:$E$72,C$1) -> 3 | D4: =SUMIFS(Features!$M$2:$M$72,Features!$B$2:$B$72,$A4,Features!$E$2:$E$72,D$1) -> 5 | E4: =SUMIFS(Features!$M$2:$M$72,Features!$B$2:$B$72,$A4,Features!$E$2:$E$72,E$1) -> 0 | F4: =SUMIFS(Features!$M$2:$M$72,Features!$B$2:$B$72,$A4,Features!$E$2:$E$72,F$1) -> 0 | G4: =SUM(B4:F4) -> 8
A5: Agents & Pipeline | B5: =SUMIFS(Features!$M$2:$M$72,Features!$B$2:$B$72,$A5,Features!$E$2:$E$72,B$1) -> 0 | C5: =SUMIFS(Features!$M$2:$M$72,Features!$B$2:$B$72,$A5,Features!$E$2:$E$72,C$1) -> 3 | D5: =SUMIFS(Features!$M$2:$M$72,Features!$B$2:$B$72,$A5,Features!$E$2:$E$72,D$1) -> 12 | E5: =SUMIFS(Features!$M$2:$M$72,Features!$B$2:$B$72,$A5,Features!$E$2:$E$72,E$1) -> 12 | F5: =SUMIFS(Features!$M$2:$M$72,Features!$B$2:$B$72,$A5,Features!$E$2:$E$72,F$1) -> 0 | G5: =SUM(B5:F5) -> 27
A6: Memory | B6: =SUMIFS(Features!$M$2:$M$72,Features!$B$2:$B$72,$A6,Features!$E$2:$E$72,B$1) -> 0 | C6: =SUMIFS(Features!$M$2:$M$72,Features!$B$2:$B$72,$A6,Features!$E$2:$E$72,C$1) -> 0 | D6: =SUMIFS(Features!$M$2:$M$72,Features!$B$2:$B$72,$A6,Features!$E$2:$E$72,D$1) -> 8 | E6: =SUMIFS(Features!$M$2:$M$72,Features!$B$2:$B$72,$A6,Features!$E$2:$E$72,E$1) -> 5 | F6: =SUMIFS(Features!$M$2:$M$72,Features!$B$2:$B$72,$A6,Features!$E$2:$E$72,F$1) -> 0 | G6: =SUM(B6:F6) -> 13
A7: Editor | B7: =SUMIFS(Features!$M$2:$M$72,Features!$B$2:$B$72,$A7,Features!$E$2:$E$72,B$1) -> 0 | C7: =SUMIFS(Features!$M$2:$M$72,Features!$B$2:$B$72,$A7,Features!$E$2:$E$72,C$1) -> 4 | D7: =SUMIFS(Features!$M$2:$M$72,Features!$B$2:$B$72,$A7,Features!$E$2:$E$72,D$1) -> 2 | E7: =SUMIFS(Features!$M$2:$M$72,Features!$B$2:$B$72,$A7,Features!$E$2:$E$72,E$1) -> 2 | F7: =SUMIFS(Features!$M$2:$M$72,Features!$B$2:$B$72,$A7,Features!$E$2:$E$72,F$1) -> 0 | G7: =SUM(B7:F7) -> 8
A8: Continuum Integration | B8: =SUMIFS(Features!$M$2:$M$72,Features!$B$2:$B$72,$A8,Features!$E$2:$E$72,B$1) -> 0 | C8: =SUMIFS(Features!$M$2:$M$72,Features!$B$2:$B$72,$A8,Features!$E$2:$E$72,C$1) -> 6 | D8: =SUMIFS(Features!$M$2:$M$72,Features!$B$2:$B$72,$A8,Features!$E$2:$E$72,D$1) -> 14 | E8: =SUMIFS(Features!$M$2:$M$72,Features!$B$2:$B$72,$A8,Features!$E$2:$E$72,E$1) -> 4 | F8: =SUMIFS(Features!$M$2:$M$72,Features!$B$2:$B$72,$A8,Features!$E$2:$E$72,F$1) -> 0 | G8: =SUM(B8:F8) -> 24
A9: ChickletFlow Integration | B9: =SUMIFS(Features!$M$2:$M$72,Features!$B$2:$B$72,$A9,Features!$E$2:$E$72,B$1) -> 0 | C9: =SUMIFS(Features!$M$2:$M$72,Features!$B$2:$B$72,$A9,Features!$E$2:$E$72,C$1) -> 0 | D9: =SUMIFS(Features!$M$2:$M$72,Features!$B$2:$B$72,$A9,Features!$E$2:$E$72,D$1) -> 16 | E9: =SUMIFS(Features!$M$2:$M$72,Features!$B$2:$B$72,$A9,Features!$E$2:$E$72,E$1) -> 4 | F9: =SUMIFS(Features!$M$2:$M$72,Features!$B$2:$B$72,$A9,Features!$E$2:$E$72,F$1) -> 0 | G9: =SUM(B9:F9) -> 20
A10: Cross-Product | B10: =SUMIFS(Features!$M$2:$M$72,Features!$B$2:$B$72,$A10,Features!$E$2:$E$72,B$1) -> 2 | C10: =SUMIFS(Features!$M$2:$M$72,Features!$B$2:$B$72,$A10,Features!$E$2:$E$72,C$1) -> 3 | D10: =SUMIFS(Features!$M$2:$M$72,Features!$B$2:$B$72,$A10,Features!$E$2:$E$72,D$1) -> 0 | E10: =SUMIFS(Features!$M$2:$M$72,Features!$B$2:$B$72,$A10,Features!$E$2:$E$72,E$1) -> 3 | F10: =SUMIFS(Features!$M$2:$M$72,Features!$B$2:$B$72,$A10,Features!$E$2:$E$72,F$1) -> 3 | G10: =SUM(B10:F10) -> 11
A11: Release & Governance | B11: =SUMIFS(Features!$M$2:$M$72,Features!$B$2:$B$72,$A11,Features!$E$2:$E$72,B$1) -> 1 | C11: =SUMIFS(Features!$M$2:$M$72,Features!$B$2:$B$72,$A11,Features!$E$2:$E$72,C$1) -> 0 | D11: =SUMIFS(Features!$M$2:$M$72,Features!$B$2:$B$72,$A11,Features!$E$2:$E$72,D$1) -> 0 | E11: =SUMIFS(Features!$M$2:$M$72,Features!$B$2:$B$72,$A11,Features!$E$2:$E$72,E$1) -> 0 | F11: =SUMIFS(Features!$M$2:$M$72,Features!$B$2:$B$72,$A11,Features!$E$2:$E$72,F$1) -> 8 | G11: =SUM(B11:F11) -> 9
A12: Total | B12: =SUM(B2:B11) -> 13 | C12: =SUM(C2:C11) -> 36 | D12: =SUM(D2:D11) -> 67 | E12: =SUM(E2:E11) -> 35 | F12: =SUM(F2:F11) -> 18 | G12: =SUM(G2:G11) -> 169
A14: Person-weeks are first-pass estimates. Divide by team size and release duration to check capacity.

Sheet Risks & Questions
A1: Risk | B1: Impact | C1: Mitigation | D1: Related
A2: Azure OpenAI quota/model availability delays | B2: High | C2: Request quota in week 1; keep adapter ready for Claude on Foundry / alternate region | D2: A2
A3: Holiday weeks (W9-W10, Dec 21 - Jan 1) reduce capacity | B3: Med | C3: MVP go-live set in W8; W9-10 are hypercare/buffer only | D3: M4, M5
A4: EDMX download requires XSUAA auth | B4: Med | C4: BTP trial or bearer token path; fall back to catalog-only metadata | D4: B3
A5: ChickletFlow has no auth today; exposing it on Azure is risky | B5: High | C5: Entra + service tokens (H1) must land before any public ingress | D5: H1
A6: Three-team contract drift (IDs, statuses) | B6: High | C6: Contract sign-off at M2; versioned events; contract tests in CI | D6: I2
A7: Retrieval quality limits Clean Core accuracy | B7: High | C7: Eval harness (B8) gates KB changes; coverage gap closure (B5) | D7: B5, B8
A8: Client data residency / tenant isolation | B8: High | C8: Per-client index filter, per-client deployment template, private networking | D8: A10, A11, E5
A9: Cost growth from AI Search + OpenAI usage | B9: Med | C9: Budgets and token metering from MVP (A8, D6) | D9: A8
A10: Team capacity unknown (owners are TBD) | B10: High | C10: Assign owners in Features sheet; use Person-Weeks column to check load by workstream | D10: All
A13: Open decisions
A14: 1. Central multi-tenant Deloitte instance vs per-client deployment? (drives A11, E5)
A15: 2. Which chat model is approved/quota-available in your Azure region?
A16: 3. Does darkhorse-mcp already serve HTTP or only stdio? (confirm before C2)
A17: 4. Who owns each workstream (owners are TBD)?
A18: 5. Should Continuum remain invite-only for external client users, or federate client identities (Entra B2B)?
A19: 6. Which Continuum approval state should trigger DarkHorse (APPROVED vs PUBLISHED)?
